<?xml version="1.0" ?>
<!-- =================================================================================== -->
<!-- |    This document was autogenerated by xacro from manp.xacro                     | -->
<!-- |    EDITING THIS FILE BY HAND IS NOT RECOMMENDED                                 | -->
<!-- =================================================================================== -->
<robot name="manp" xmlns:xacro="http://www.ros.org/wiki/xacro">
  <link name="world"/>
  <joint name="world_to_base" type="continuous">
    <parent link="world"/>
    <child link="base_link"/>
    <origin xyz="0 0 0"/>
    <axis xyz="0 0 1"/>
  </joint>
  <link name="base_link">
    <visual>
      <geometry>
        <cylinder length="2" radius="3"/>
      </geometry>
      <origin xyz="0 0 1"/>
    </visual>
    <inertial>
      <mass value="1"/>
      <inertia ixx="1" ixy="0.0" ixz="0.0" iyy="1" iyz="0.0" izz="1"/>
    </inertial>
  </link>
  <joint name="base_to_link1" type="fixed">
    <parent link="base_link"/>
    <child link="link1"/>
    <origin rpy="0 0 0" xyz="0 0 2"/>
    <axis xyz="0 1 0"/>
  </joint>
  <link name="link1">
    <visual>
      <geometry>
        <box size="1 1 2"/>
      </geometry>
      <origin xyz="0 0 1"/>
    </visual>
    <inertial>
      <mass value="1"/>
      <inertia ixx="1" ixy="0.0" ixz="0.0" iyy="1" iyz="0.0" izz="1"/>
    </inertial>
  </link>
  <joint name="link1_to_link2" type="continuous">
    <parent link="link1"/>
    <child link="link2"/>
    <origin rpy="0 0 0" xyz="0 -1 1.5"/>
    <axis xyz="0 1 0"/>
  </joint>
  <link name="link2">
    <visual>
      <geometry>
        <box size="1 1 5"/>
      </geometry>
      <origin xyz="0 0 2.5"/>
    </visual>
    <inertial>
      <mass value="1"/>
      <inertia ixx="1" ixy="0.0" ixz="0.0" iyy="1" iyz="0.0" izz="1"/>
    </inertial>
  </link>
  <joint name="link2_to_link3" type="continuous">
    <parent link="link2"/>
    <child link="link3"/>
    <origin xyz="0 1 4.5"/>
    <axis xyz="0 1 0"/>
  </joint>
  <link name="link3">
    <visual>
      <geometry>
        <box size="1 1 5"/>
      </geometry>
      <origin xyz="0 0 2"/>
    </visual>
    <inertial>
      <mass value="1"/>
      <inertia ixx="1" ixy="0.0" ixz="0.0" iyy="1" iyz="0.0" izz="1"/>
    </inertial>
  </link>
</robot>
